[
  {
    "py/object": "objects.Link",
    "src": {
      "py/object": "objects.Exception",
      "type": "java.io.IOException",
      "message": "Injecting failure during merge"
    },
    "dst": {
      "py/object": "objects.Exception",
      "type": "java.io.IOException",
      "message": "There appears to be an out-of-order edit in the edit log.  We expected txid 11, but got txid 10."
    }
  }
]
